Workbook

Sheet MASIVO
A1: AplicaContrapago | B1: valor declarado | C1: Peso | D1: Largo | E1: Ancho | F1: Alto | G1: dice contener | H1: ciudad destino | I1: codigo destino | J1: numero documento | K1: nombre | L1: primer apellido | M1: segundo apellido | N1: telefono | O1: direccion | P1: correo | Q1: Observaciones | R1: transportadora | S1: pais
A2: TRUE | B2: 50000 | C2: 1 | D2: 1 | E2: 1 | F2: 1 | G2: prueba 1 | H2: BOGOTA, DISTRITO CAPITAL/BOGOTA, D.C. | I2: =IFERROR(VLOOKUP(H2,'CODIGO CIUDADES'!A:B,2,0)," ") -> 11001000 | J2: 123456789 | K2: Cliente 1 | L2: 0 | M2: 0 | N2: 3123456789 | O2: Calle 1 # 1-2 | P2: 99envios@gmail.com | Q2: producto | R2: interrapidisimo | S2: colombia
A3: TRUE | B3: 70000 | C3: 1 | D3: 1 | E3: 1 | F3: 1 | G3: prueba 2 | H3: ARMENIA/QUINDIO | I3: =IFERROR(VLOOKUP(H3,'CODIGO CIUDADES'!A:B,2,0)," ") -> 63001000 | J3: 123456789 | K3: Cliente2 | L3: 0 | M3: 0 | N3: 3123456789 | O3: Calle 1 # 1-2 apto 101 | P3: 99envios@gmail.com | Q3: producto | R3: interrapidisimo | S3: colombia
A4: TRUE | B4: 90000 | C4: 1 | D4: 1 | E4: 1 | F4: 1 | G4: prueba 3 | H4: MEDELLIN/ANTIOQUIA | I4: =IFERROR(VLOOKUP(H4,'CODIGO CIUDADES'!A:B,2,0)," ") -> 05001000 | J4: 123456789 | K4: Cliente 3 | L4: 0 | M4: 0 | N4: 3123456789 | O4: Calle 1 # 1-2 conjunto cielo | P4: 99envios@gmail.com | Q4: producto | R4: interrapidisimo | S4: colombia
I13: =IFERROR(VLOOKUP(H13,'CODIGO CIUDADES'!A:B,2,0)," ")
I14: =IFERROR(VLOOKUP(H14,'CODIGO CIUDADES'!A:B,2,0)," ")
I15: =IFERROR(VLOOKUP(H15,'CODIGO CIUDADES'!A:B,2,0)," ")
I16: =IFERROR(VLOOKUP(H16,'CODIGO CIUDADES'!A:B,2,0)," ")
I17: =IFERROR(VLOOKUP(H17,'CODIGO CIUDADES'!A:B,2,0)," ")
I18: =IFERROR(VLOOKUP(H18,'CODIGO CIUDADES'!A:B,2,0)," ")
I19: =IFERROR(VLOOKUP(H19,'CODIGO CIUDADES'!A:B,2,0)," ")
I20: =IFERROR(VLOOKUP(H20,'CODIGO CIUDADES'!A:B,2,0)," ")
I21: =IFERROR(VLOOKUP(H21,'CODIGO CIUDADES'!A:B,2,0)," ")
I22: =IFERROR(VLOOKUP(H22,'CODIGO CIUDADES'!A:B,2,0)," ")
I23: =IFERROR(VLOOKUP(H23,'CODIGO CIUDADES'!A:B,2,0)," ")
I24: =IFERROR(VLOOKUP(H24,'CODIGO CIUDADES'!A:B,2,0)," ")
... I98: =IFERROR(VLOOKUP(H98,'CODIGO CIUDADES'!A:B,2,0)," ")

Sheet CODIGO CIUDADES
A1: MEDELLIN/ANTIOQUIA | B1: 05001000
A2: PALMITAS/ANTIOQUIA | B2: 05001001
A3: SANTA ELENA/ANTIOQUIA | B3: 05001004
A4: ALTAVISTA/ANTIOQUIA | B4: 05001009
A5: AGUAS FRIAS/ANTIOQUIA | B5: 05001010
A6: SAN JOSE DEL MANZANILLO/ANTIOQUIA | B6: 05001013
A7: BARRO BLANCO/ANTIOQUIA | B7: 05001014
A8: EL CERRO/ANTIOQUIA | B8: 05001015
A9: EL PATIO/ANTIOQUIA | B9: 05001017
A10: EL PLACER/ANTIOQUIA | B10: 05001018
A11: EL PLAN/ANTIOQUIA | B11: 05001019
A12: LA ALDEA/ANTIOQUIA | B12: 05001022
... A1504: SANTA ROSA DE VITERBO/BOYACA | B1504: 15693000
A1505: EL IMPERIO/BOYACA | B1505: 15693002
A1506: SANTA SOFIA/BOYACA | B1506: 15696000
A1507: SATIVANORTE/BOYACA | B1507: 15720000
A1508: SATIVA VIEJO/BOYACA | B1508: 15720001
A1509: SATIVASUR/BOYACA | B1509: 15723000
A1510: SIACHOQUE/BOYACA | B1510: 15740000
A1511: SOATA/BOYACA | B1511: 15753000
A1512: SOCOTA/BOYACA | B1512: 15755000
A1513: LOS PINOS/BOYACA | B1513: 15755004
A1514: SOCHA/BOYACA | B1514: 15757000
A1515: SANTA TERESA/BOYACA | B1515: 15757001
A1516: SOCHA VIEJO/BOYACA | B1516: 15757003
A1517: SOGAMOSO/BOYACA | B1517: 15759000
A1518: MORCA/BOYACA | B1518: 15759001
A1519: VANEGAS/BOYACA | B1519: 15759003
A1520: EL CRUCERO/BOYACA | B1520: 15759005
A1521: ALCAPARRAL/BOYACA | B1521: 15759006
A1522: MILAGRO Y PLAYITA/BOYACA | B1522: 15759007
A1523: SOMONDOCO/BOYACA | B1523: 15761000
A1524: SORA/BOYACA | B1524: 15762000
A1525: SOTAQUIRA/BOYACA | B1525: 15763000
A1526: BOSIGAS/BOYACA | B1526: 15763002
A1527: CARREÑO/BOYACA | B1527: 15763003
... A1846: GIBRALTAR/CAQUETA | B1846: 18753010
A1847: LOS POZOS/CAQUETA | B1847: 18753011
A1848: SANTA ROSA/CAQUETA | B1848: 18753012
A1849: TRONCALES/CAQUETA | B1849: 18753013
...
